[2025-06-01T10:40:58.275+0200] {task_context_logger.py:104} ERROR - Executor reports task instance <TaskInstance: macro_trading_dag.fetch_fred_data scheduled__2025-05-31T08:00:00+00:00 [queued]> finished (failed) although the task says it's queued. (Info: None) Was the task killed externally?
